<?xml version="1.0"?>
<robot xmlns:xacro="http://ros.org/wiki/xacro">
  <xacro:macro name="forklift_attachment" params="parent *origin">
    <!-- Mast -->
    <joint name="mast_joint" type="fixed">
      <xacro:insert_block name="origin"/>
      <parent link="${parent}"/>
      <child link="mast_link"/>
    </joint>
    
    <link name="mast_link">
      <visual>
        <geometry>
          <mesh filename="package://raspimouse_description/meshes/dae/attachment/mast.dae"/>
        </geometry>
      </visual>
      <collision>
        <geometry>
          <box size="0.05 0.05 0.3"/>
        </geometry>
      </collision>
      <inertial>
        <mass value="0.5"/>
        <inertia ixx="0.001" ixy="0" ixz="0" iyy="0.001" iyz="0" izz="0.0005"/>
      </inertial>
    </link>

    <!-- Fork -->
    <joint name="fork_joint" type="prismatic">
      <parent link="mast_link"/>
      <child link="fork_link"/>
      <origin xyz="0 0 0.15" rpy="0 0 0"/>
      <axis xyz="0 0 1"/>
      <limit lower="0" upper="0.2" effort="100" velocity="0.1"/>
    </joint>

    <link name="fork_link">
      <visual>
        <geometry>
          <mesh filename="package://raspimouse_description/meshes/dae/attachment/fork.dae"/>
        </geometry>
      </visual>
      <collision>
        <geometry>
          <box size="0.2 0.1 0.02"/>
        </geometry>
      </collision>
      <inertial>
        <mass value="0.3"/>
        <inertia ixx="0.0002" ixy="0" ixz="0" iyy="0.0005" iyz="0" izz="0.0007"/>
      </inertial>
    </link>
  </xacro:macro>
</robot>