<?xml version="1.0"?>
<robot name="quadrotor">
    <!-- Main body link -->
    <link name="base_link">
        <inertial>
            <mass value="1.5"/>
            <origin xyz="0 0 0" rpy="0 0 0"/>
            <inertia ixx="0.0347563" ixy="0" ixz="0"
                     iyy="0.0458929" iyz="0"
                     izz="0.0977" />
        </inertial>
        
        <visual>
            <origin xyz="0 0 0" rpy="0 0 0"/>
            <geometry>
                <box size="0.4 0.4 0.1"/>
            </geometry>
            <material name="blue">
                <color rgba="0 0 0.8 1"/>
            </material>
        </visual>
        
        <collision>
            <origin xyz="0 0 0" rpy="0 0 0"/>
            <geometry>
                <box size="0.4 0.4 0.1"/>
            </geometry>
        </collision>
    </link>

    <!-- Front Right Rotor -->
    <link name="rotor_front_right">
        <inertial>
            <mass value="0.1"/>
            <origin xyz="0 0 0.02" rpy="0 0 0"/>
            <inertia ixx="0.0001" ixy="0" ixz="0"
                     iyy="0.0001" iyz="0"
                     izz="0.0002" />
        </inertial>
        
        <visual>
            <origin xyz="0 0 0" rpy="0 0 0"/>
            <geometry>
                <cylinder radius="0.1" length="0.02"/>
            </geometry>
            <material name="red">
                <color rgba="0.8 0 0 1"/>
            </material>
        </visual>
        
        <collision>
            <origin xyz="0 0 0" rpy="0 0 0"/>
            <geometry>
                <cylinder radius="0.1" length="0.02"/>
            </geometry>
        </collision>
    </link>

    <joint name="rotor_front_right_joint" type="continuous">
        <parent link="base_link"/>
        <child link="rotor_front_right"/>
        <origin xyz="0.15 -0.15 0.05" rpy="0 0 0"/>
        <axis xyz="0 0 1"/>
        <dynamics damping="0.01" friction="0.01"/>
    </joint>

    <!-- Front Left Rotor -->
    <link name="rotor_front_left">
        <inertial>
            <mass value="0.1"/>
            <origin xyz="0 0 0.02" rpy="0 0 0"/>
            <inertia ixx="0.0001" ixy="0" ixz="0"
                     iyy="0.0001" iyz="0"
                     izz="0.0002" />
        </inertial>
        
        <visual>
            <origin xyz="0 0 0" rpy="0 0 0"/>
            <geometry>
                <cylinder radius="0.1" length="0.02"/>
            </geometry>
            <material name="red">
                <color rgba="0.8 0 0 1"/>
            </material>
        </visual>
        
        <collision>
            <origin xyz="0 0 0" rpy="0 0 0"/>
            <geometry>
                <cylinder radius="0.1" length="0.02"/>
            </geometry>
        </collision>
    </link>

    <joint name="rotor_front_left_joint" type="continuous">
        <parent link="base_link"/>
        <child link="rotor_front_left"/>
        <origin xyz="0.15 0.15 0.05" rpy="0 0 0"/>
        <axis xyz="0 0 -1"/>  <!-- Note: Opposite rotation direction -->
        <dynamics damping="0.01" friction="0.01"/>
    </joint>

    <!-- Rear Right Rotor -->
    <link name="rotor_rear_right">
        <inertial>
            <mass value="0.1"/>
            <origin xyz="0 0 0.02" rpy="0 0 0"/>
            <inertia ixx="0.0001" ixy="0" ixz="0"
                     iyy="0.0001" iyz="0"
                     izz="0.0002" />
        </inertial>
        
        <visual>
            <origin xyz="0 0 0" rpy="0 0 0"/>
            <geometry>
                <cylinder radius="0.1" length="0.02"/>
            </geometry>
            <material name="red">
                <color rgba="0.8 0 0 1"/>
            </material>
        </visual>
        
        <collision>
            <origin xyz="0 0 0" rpy="0 0 0"/>
            <geometry>
                <cylinder radius="0.1" length="0.02"/>
            </geometry>
        </collision>
    </link>

    <joint name="rotor_rear_right_joint" type="continuous">
        <parent link="base_link"/>
        <child link="rotor_rear_right"/>
        <origin xyz="-0.15 -0.15 0.05" rpy="0 0 0"/>
        <axis xyz="0 0 -1"/>  <!-- Note: Opposite rotation direction -->
        <dynamics damping="0.01" friction="0.01"/>
    </joint>

    <!-- Rear Left Rotor -->
    <link name="rotor_rear_left">
        <inertial>
            <mass value="0.1"/>
            <origin xyz="0 0 0.02" rpy="0 0 0"/>
            <inertia ixx="0.0001" ixy="0" ixz="0"
                     iyy="0.0001" iyz="0"
                     izz="0.0002" />
        </inertial>
        
        <visual>
            <origin xyz="0 0 0" rpy="0 0 0"/>
            <geometry>
                <cylinder radius="0.1" length="0.02"/>
            </geometry>
            <material name="red">
                <color rgba="0.8 0 0 1"/>
            </material>
        </visual>
        
        <collision>
            <origin xyz="0 0 0" rpy="0 0 0"/>
            <geometry>
                <cylinder radius="0.1" length="0.02"/>
            </geometry>
        </collision>
    </link>

    <joint name="rotor_rear_left_joint" type="continuous">
        <parent link="base_link"/>
        <child link="rotor_rear_left"/>
        <origin xyz="-0.15 0.15 0.05" rpy="0 0 0"/>
        <axis xyz="0 0 1"/>
        <dynamics damping="0.01" friction="0.01"/>
    </joint>

</robot>